package lectures.Java_ExceptionHandling_20;

import java.util.Scanner;
//Re-throwing an exception
class Alpha1
{
	void alpha() throws ArithmeticException
	{
		System.out.println("Connection to Calc app is established");
		try
		{
		Scanner scan=new Scanner(System.in);
		System.out.println("Enter the first num to divide");
		int num1=scan.nextInt();
		System.out.println("Enter the 2nd num to divide");
		int num2=scan.nextInt();
		
		 int res=num1/num2;
		
		System.out.println("The res is "+ res);
		}
		catch(ArithmeticException e)
		{
		System.out.println("Exception handled in alpha only");	
		throw e;
		}
		finally {
		System.out.println("Connection is terminated");
		}
	}
}

public class ThrowKeyword_ReThrowing_Exception_7 {

	public static void main(String[] args) 
	{
		try
		{
		System.out.println("Main method connection");
		Alpha1 a=new Alpha1();
		a.alpha();
		}
		catch(ArithmeticException e)
		{
		System.out.println("Exception handled in main");
		}

	}

}

